Workbook

Sheet Executive Summary
A1: Metric | B1: Value
A2: Total Areas | B2: 4
A3: Total Zip Codes | B3: 156
A4: Total Accounts | B4: 1699
A5: Phoenix West Accounts | B5: 529
A6: Phoenix Central Accounts | B6: 527
A7: Phoenix East Accounts | B7: 570
A8: Tucson Accounts | B8: 73
A9: Phoenix West Zip Codes | B9: 45
A10: Phoenix Central Zip Codes | B10: 49
A11: Phoenix East Zip Codes | B11: 36
A12: Tucson Zip Codes | B12: 26

Sheet Area Summary
A1: Territory ID # | B1: Area | C1: NumZips | D1: NumAccounts
A2: 0 | B2: Central | C2: 49 | D2: 527
A3: 1 | B3: East | C3: 36 | D3: 570
A4: 2 | B4: Tucson | C4: 26 | D4: 73
A5: 3 | B5: West | C5: 45 | D5: 529
A7: LINK TO MAP VISUAL FOR PHOENIX

Sheet Zip Code Summary
A1: ZipCode | B1: Area | C1: AccountCount
A2: 85003 | B2: Central | C2: 6
A3: 85006 | B3: Central | C3: 4
A4: 85007 | B4: Central | C4: 3
A5: 85008 | B5: Central | C5: 4
A6: 85009 | B6: Central | C6: 3
A7: 85012 | B7: Central | C7: 6
A8: 85013 | B8: Central | C8: 5
A9: 85014 | B9: Central | C9: 9
A10: 85015 | B10: Central | C10: 9
A11: 85016 | B11: Central | C11: 9
A12: 85017 | B12: Central | C12: 1
A13: 85018 | B13: Central | C13: 25
... A157: 85396 | B157: West | C157: 12

Sheet All Accounts
A1: SF Customer Number | B1: Name | C1: ShippingStreet | D1: Shipping City | E1: ShippingStateCode | F1: ZipCode | G1: Area | H1: Source
A2: A-011013 | B2: DePonti, Cindy | C2: 81 W Lewis Ave | D2: =VLOOKUP(F2, ZipTable!A:B, 2, FALSE) -> PHOENIX | E2: AZ | F2: 85003 | G2: Central | H2: Phoenix
A3: A-002021 | B3: Goodell, Estelle | C3: 76 W Lewis Ave. | D3: =VLOOKUP(F3, ZipTable!A:B, 2, FALSE) -> PHOENIX | E3: AZ | F3: 85003 | G3: Central | H3: Phoenix
A4: A-009708 | B4: Haggerty, Paul | C4: 310 W. Portland St. | D4: =VLOOKUP(F4, ZipTable!A:B, 2, FALSE) -> PHOENIX | E4: AZ | F4: 85003 | G4: Central | H4: Phoenix
A5: A-000863 | B5: Standerfer, Robert | C5: 501 W Wilshire Dr | D5: =VLOOKUP(F5, ZipTable!A:B, 2, FALSE) -> PHOENIX | E5: AZ | F5: 85003 | G5: Central | H5: Phoenix
A6: A-008363 | B6: Thatcher, Craig | C6: 314 W. Monte Vista Rd. | D6: =VLOOKUP(F6, ZipTable!A:B, 2, FALSE) -> PHOENIX | E6: AZ | F6: 85003 | G6: Central | H6: Phoenix
A7: A-008009 | B7: Turner, Wayne | C7: 326 W Portland St. | D7: =VLOOKUP(F7, ZipTable!A:B, 2, FALSE) -> PHOENIX | E7: AZ | F7: 85003 | G7: Central | H7: Phoenix
A8: A-002850 | B8: Dominguez, Antonio | C8: 1911 E Willetta St | D8: =VLOOKUP(F8, ZipTable!A:B, 2, FALSE) -> PHOENIX | E8: AZ | F8: 85006 | G8: Central | H8: Phoenix
A9: A-064816 | B9: Fontes, Adrian | C9: 801 East Windsor Avenue | D9: =VLOOKUP(F9, ZipTable!A:B, 2, FALSE) -> PHOENIX | E9: AZ | F9: 85006 | G9: Central | H9: Phoenix
A10: A-023454 | B10: Gilkes, Beaulah | C10: 2302 N Dayton Street | D10: =VLOOKUP(F10, ZipTable!A:B, 2, FALSE) -> PHOENIX | E10: AZ | F10: 85006 | G10: Central | H10: Phoenix
A11: A-001337 | B11: Palmer, John | C11: 914 N. 9th St. | D11: =VLOOKUP(F11, ZipTable!A:B, 2, FALSE) -> PHOENIX | E11: AZ | F11: 85006 | G11: Central | H11: Phoenix
A12: A-023456 | B12: Beck, Andy | C12: 1746 N 15th Avenue | D12: =VLOOKUP(F12, ZipTable!A:B, 2, FALSE) -> PHOENIX | E12: AZ | F12: 85007 | G12: Central | H12: Phoenix
A13: A-034156 | B13: Reams, Brianna | C13: 1605 West Wilshire Drive | D13: =VLOOKUP(F13, ZipTable!A:B, 2, FALSE) -> PHOENIX | E13: AZ | F13: 85007 | G13: Central | H13: Phoenix
... A212: A-008428 | B212: Compton, Sophie | C212: 340 E. Ivy St. | D212: =VLOOKUP(F212, ZipTable!A:B, 2, FALSE) -> MESA | E212: AZ | F212: 85201 | G212: Central | H212: Phoenix
A213: A-055254 | B213: Keller Residence | C213: 1110 W Hillview St | D213: =VLOOKUP(F213, ZipTable!A:B, 2, FALSE) -> MESA | F213: 85201 | G213: Central | H213: Phoenix
A214: A-005625 | B214: Zraket, Alexis | C214: 326 E. Hope St. | D214: =VLOOKUP(F214, ZipTable!A:B, 2, FALSE) -> MESA | E214: AZ | F214: 85201 | G214: Central | H214: Phoenix
A215: A-006577 | B215: Baca, Senovia | C215: 2231 W Catalina Ave | D215: =VLOOKUP(F215, ZipTable!A:B, 2, FALSE) -> MESA | E215: AZ | F215: 85202 | G215: Central | H215: Phoenix
A216: A-004965 | B216: Clavel, Crystal and Greg | C216: 2243 W Plata Ave | D216: =VLOOKUP(F216, ZipTable!A:B, 2, FALSE) -> MESA | E216: AZ | F216: 85202 | G216: Central | H216: Phoenix
A217: A-007768 | B217: Galusha, Melanie | C217: 2428 W. Keating Ave | D217: =VLOOKUP(F217, ZipTable!A:B, 2, FALSE) -> MESA | E217: AZ | F217: 85202 | G217: Central | H217: Phoenix
A218: A-031443 | B218: Koza, Dana | C218: 1517 West Kiowa Avenue | D218: =VLOOKUP(F218, ZipTable!A:B, 2, FALSE) -> MESA | E218: AZ | F218: 85202 | G218: Central | H218: Phoenix
A219: A-011731 | B219: Langham, David | C219: 2330 W Calle Iglesia Ave | D219: =VLOOKUP(F219, ZipTable!A:B, 2, FALSE) -> MESA | E219: AZ | F219: 85202 | G219: Central | H219: Phoenix
A220: A-034415 | B220: Perez, Kaitlin | C220: 3028 South Santa Barbara Circle | D220: =VLOOKUP(F220, ZipTable!A:B, 2, FALSE) -> MESA | E220: AZ | F220: 85202 | G220: Central | H220: Phoenix
A221: A-009027 | B221: Pruitt, Donald | C221: 2919 S Cottonwood Ln | D221: =VLOOKUP(F221, ZipTable!A:B, 2, FALSE) -> MESA | E221: AZ | F221: 85202 | G221: Central | H221: Phoenix
A222: A-002492 | B222: Thomas, Chelsea and Scott | C222: 2566 W Monte Ave | D222: =VLOOKUP(F222, ZipTable!A:B, 2, FALSE) -> MESA | E222: AZ | F222: 85202 | G222: Central | H222: Phoenix
A223: A-006607 | B223: Tran, Bac | C223: 2365 S. Paseo Loma Circle | D223: =VLOOKUP(F223, ZipTable!A:B, 2, FALSE) -> MESA | E223: AZ | F223: 85202 | G223: Central | H223: Phoenix
A224: A-066276 | B224: Azab, Bilal | C224: 1236 East Granada Street | D224: =VLOOKUP(F224, ZipTable!A:B, 2, FALSE) -> MESA | E224: AZ | F224: 85203 | G224: Central | H224: Phoenix
A225: A-008651 | B225: Breinholt, Clareen | C225: 845 N. Kachina Cir | D225: =VLOOKUP(F225, ZipTable!A:B, 2, FALSE) -> MESA | E225: AZ | F225: 85203 | G225: Central | H225: Phoenix
... A754: A-024114 | B754: Hamilton, Sandra | C754: 9011 E Hobart Street | D754: =VLOOKUP(F754, ZipTable!A:B, 2, FALSE) -> MESA | E754: AZ | F754: 85207 | G754: East | H754: Phoenix
A755: A-055262 | B755: Harris Residence | C755: 7642 East Hermosa Vista Drive | D755: =VLOOKUP(F755, ZipTable!A:B, 2, FALSE) -> MESA | F755: 85207 | G755: East | H755: Phoenix
A756: A-005547 | B756: Jacobs, Pat | C756: 8024 E. Fountain St. | D756: =VLOOKUP(F756, ZipTable!A:B, 2, FALSE) -> MESA | E756: AZ | F756: 85207 | G756: East | H756: Phoenix
A757: A-066496 | B757: James, Frank | C757: 2241 North Hillridge | D757: =VLOOKUP(F757, ZipTable!A:B, 2, FALSE) -> MESA | E757: AZ | F757: 85207 | G757: East | H757: Phoenix
A758: A-050523 | B758: Koufidakis, Angela | C758: 7544 East Laurel Street | D758: =VLOOKUP(F758, ZipTable!A:B, 2, FALSE) -> MESA | E758: AZ | F758: 85207 | G758: East | H758: Phoenix
A759: A-068557 | B759: Lanciloti, Tamara | C759: 3060 North Ridgecrest unit 172 | D759: =VLOOKUP(F759, ZipTable!A:B, 2, FALSE) -> MESA | E759: AZ | F759: 85207 | G759: East | H759: Phoenix
A760: A-056454 | B760: Looff, Kevin | C760: 9018 East Range Rider Trail | D760: =VLOOKUP(F760, ZipTable!A:B, 2, FALSE) -> MESA | E760: AZ | F760: 85207 | G760: East | H760: Phoenix
A761: A-007701 | B761: Mason, Kris | C761: 7343 E. Sierra Morena Cir. | D761: =VLOOKUP(F761, ZipTable!A:B, 2, FALSE) -> MESA | E761: AZ | F761: 85207 | G761: East | H761: Phoenix
A762: A-006597 | B762: Miroballi, Barbara | C762: 1253 N 86th Pl | D762: =VLOOKUP(F762, ZipTable!A:B, 2, FALSE) -> MESA | E762: AZ | F762: 85207 | G762: East | H762: Phoenix
A763: A-005654 | B763: Mohr, Donna | C763: 7130 E. Saddleback St. #21 | D763: =VLOOKUP(F763, ZipTable!A:B, 2, FALSE) -> MESA | E763: AZ | F763: 85207 | G763: East | H763: Phoenix
A764: A-001971 | B764: Mordhorst, Becky | C764: 9655 E Glencove Circle | D764: =VLOOKUP(F764, ZipTable!A:B, 2, FALSE) -> MESA | E764: AZ | F764: 85207 | G764: East | H764: Phoenix
A765: A-024115 | B765: Neumeyer, David & Pamela | C765: 2227 N Hillridge | D765: =VLOOKUP(F765, ZipTable!A:B, 2, FALSE) -> MESA | E765: AZ | F765: 85207 | G765: East | H765: Phoenix
A766: A-024116 | B766: Openshaw, Shane and Suzanne | C766: 7654 E Summit Trail St | D766: =VLOOKUP(F766, ZipTable!A:B, 2, FALSE) -> MESA | E766: AZ | F766: 85207 | G766: East | H766: Phoenix
...

Sheet West Accounts
A1: SF Customer Number | B1: Name | C1: ShippingStreet | D1: ShippingCity | E1: ShippingStateCode | F1: ZipCode | G1: Area | H1: Source
A2: A-008632 | B2: Allison, Rebecca | C2: 10636 N 11th St | D2: =VLOOKUP(F2, ZipTable!A:B, 2, FALSE) -> PHOENIX | E2: AZ | F2: 85020 | G2: West | H2: Phoenix
A3: A-007699 | B3: Asa, Sam | C3: 307 E. El Camino Dr. | D3: =VLOOKUP(F3, ZipTable!A:B, 2, FALSE) -> PHOENIX | E3: AZ | F3: 85020 | G3: West | H3: Phoenix
A4: A-049012 | B4: Batman, Ed | C4: 2022 East Gardenia Avenue | D4: =VLOOKUP(F4, ZipTable!A:B, 2, FALSE) -> PHOENIX | E4: AZ | F4: 85020 | G4: West | H4: Phoenix
A5: A-001723 | B5: Duran, Juan and Regina | C5: 824 E Royal Palm Road | D5: =VLOOKUP(F5, ZipTable!A:B, 2, FALSE) -> PHOENIX | E5: AZ | F5: 85020 | G5: West | H5: Phoenix
A6: A-008662 | B6: Gillis, Christine | C6: 1120 E Palmaire Ave | D6: =VLOOKUP(F6, ZipTable!A:B, 2, FALSE) -> PHOENIX | E6: AZ | F6: 85020 | G6: West | H6: Phoenix
A7: A-033841 | B7: Hobohm, Dan | C7: 2210 East Vista Avenue | D7: =VLOOKUP(F7, ZipTable!A:B, 2, FALSE) -> PHOENIX | E7: AZ | F7: 85020 | G7: West | H7: Phoenix
A8: A-039020 | B8: Kride, Justin | C8: 8009 North 6th Street | D8: =VLOOKUP(F8, ZipTable!A:B, 2, FALSE) -> PHOENIX | E8: AZ | F8: 85020 | G8: West | H8: Phoenix
A9: A-028201 | B9: Moore, Mary | C9: 1345 E Christy Dr | D9: =VLOOKUP(F9, ZipTable!A:B, 2, FALSE) -> PHOENIX | E9: AZ | F9: 85020 | G9: West | H9: Phoenix
A10: A-001607 | B10: Ortega, Tom and Stacia | C10: 7015 N. 2nd St. | D10: =VLOOKUP(F10, ZipTable!A:B, 2, FALSE) -> PHOENIX | E10: AZ | F10: 85020 | G10: West | H10: Phoenix
A11: A-007355 | B11: Rodelas, Raul & Angela | C11: 7114 N 23rd Pl | D11: =VLOOKUP(F11, ZipTable!A:B, 2, FALSE) -> PHOENIX | E11: AZ | F11: 85020 | G11: West | H11: Phoenix
A12: A-008764 | B12: Rogge, Cecilia and Gene | C12: 1018 E Myrtle | D12: =VLOOKUP(F12, ZipTable!A:B, 2, FALSE) -> PHOENIX | E12: AZ | F12: 85020 | G12: West | H12: Phoenix
A13: A-009407 | B13: Rusnak, Ann | C13: 7211 N. 2nd St. | D13: =VLOOKUP(F13, ZipTable!A:B, 2, FALSE) -> PHOENIX | E13: AZ | F13: 85020 | G13: West | H13: Phoenix
... A530: A-065063 | B530: Wang 2, Chris | C530: 30225 West Cheery Lynn Road | D530: =VLOOKUP(F530, ZipTable!A:B, 2, FALSE) -> BUCKEYE | E530: AZ | F530: 85396 | G530: West | H530: Phoenix

Sheet Central Accounts
A1: SF Customer Number | B1: Name | C1: ShippingStreet | D1: City | E1: ShippingStateCode | F1: ZipCode | G1: Area | H1: Source
A2: A-011013 | B2: DePonti, Cindy | C2: 81 W Lewis Ave | D2: =VLOOKUP(F2, ZipTable!A:B, 2, FALSE) -> PHOENIX | E2: AZ | F2: 85003 | G2: Central | H2: Phoenix
A3: A-002021 | B3: Goodell, Estelle | C3: 76 W Lewis Ave. | D3: =VLOOKUP(F3, ZipTable!A:B, 2, FALSE) -> PHOENIX | E3: AZ | F3: 85003 | G3: Central | H3: Phoenix
A4: A-009708 | B4: Haggerty, Paul | C4: 310 W. Portland St. | D4: =VLOOKUP(F4, ZipTable!A:B, 2, FALSE) -> PHOENIX | E4: AZ | F4: 85003 | G4: Central | H4: Phoenix
A5: A-000863 | B5: Standerfer, Robert | C5: 501 W Wilshire Dr | D5: =VLOOKUP(F5, ZipTable!A:B, 2, FALSE) -> PHOENIX | E5: AZ | F5: 85003 | G5: Central | H5: Phoenix
A6: A-008363 | B6: Thatcher, Craig | C6: 314 W. Monte Vista Rd. | D6: =VLOOKUP(F6, ZipTable!A:B, 2, FALSE) -> PHOENIX | E6: AZ | F6: 85003 | G6: Central | H6: Phoenix
A7: A-008009 | B7: Turner, Wayne | C7: 326 W Portland St. | D7: =VLOOKUP(F7, ZipTable!A:B, 2, FALSE) -> PHOENIX | E7: AZ | F7: 85003 | G7: Central | H7: Phoenix
A8: A-002850 | B8: Dominguez, Antonio | C8: 1911 E Willetta St | D8: =VLOOKUP(F8, ZipTable!A:B, 2, FALSE) -> PHOENIX | E8: AZ | F8: 85006 | G8: Central | H8: Phoenix
A9: A-064816 | B9: Fontes, Adrian | C9: 801 East Windsor Avenue | D9: =VLOOKUP(F9, ZipTable!A:B, 2, FALSE) -> PHOENIX | E9: AZ | F9: 85006 | G9: Central | H9: Phoenix
A10: A-023454 | B10: Gilkes, Beaulah | C10: 2302 N Dayton Street | D10: =VLOOKUP(F10, ZipTable!A:B, 2, FALSE) -> PHOENIX | E10: AZ | F10: 85006 | G10: Central | H10: Phoenix
A11: A-001337 | B11: Palmer, John | C11: 914 N. 9th St. | D11: =VLOOKUP(F11, ZipTable!A:B, 2, FALSE) -> PHOENIX | E11: AZ | F11: 85006 | G11: Central | H11: Phoenix
A12: A-023456 | B12: Beck, Andy | C12: 1746 N 15th Avenue | D12: =VLOOKUP(F12, ZipTable!A:B, 2, FALSE) -> PHOENIX | E12: AZ | F12: 85007 | G12: Central | H12: Phoenix
A13: A-034156 | B13: Reams, Brianna | C13: 1605 West Wilshire Drive | D13: =VLOOKUP(F13, ZipTable!A:B, 2, FALSE) -> PHOENIX | E13: AZ | F13: 85007 | G13: Central | H13: Phoenix
... A212: A-008428 | B212: Compton, Sophie | C212: 340 E. Ivy St. | D212: =VLOOKUP(F212, ZipTable!A:B, 2, FALSE) -> MESA | E212: AZ | F212: 85201 | G212: Central | H212: Phoenix
A213: A-055254 | B213: Keller Residence | C213: 1110 W Hillview St | D213: =VLOOKUP(F213, ZipTable!A:B, 2, FALSE) -> MESA | F213: 85201 | G213: Central | H213: Phoenix
A214: A-005625 | B214: Zraket, Alexis | C214: 326 E. Hope St. | D214: =VLOOKUP(F214, ZipTable!A:B, 2, FALSE) -> MESA | E214: AZ | F214: 85201 | G214: Central | H214: Phoenix
A215: A-006577 | B215: Baca, Senovia | C215: 2231 W Catalina Ave | D215: =VLOOKUP(F215, ZipTable!A:B, 2, FALSE) -> MESA | E215: AZ | F215: 85202 | G215: Central | H215: Phoenix
A216: A-004965 | B216: Clavel, Crystal and Greg | C216: 2243 W Plata Ave | D216: =VLOOKUP(F216, ZipTable!A:B, 2, FALSE) -> MESA | E216: AZ | F216: 85202 | G216: Central | H216: Phoenix
A217: A-007768 | B217: Galusha, Melanie | C217: 2428 W. Keating Ave | D217: =VLOOKUP(F217, ZipTable!A:B, 2, FALSE) -> MESA | E217: AZ | F217: 85202 | G217: Central | H217: Phoenix
A218: A-031443 | B218: Koza, Dana | C218: 1517 West Kiowa Avenue | D218: =VLOOKUP(F218, ZipTable!A:B, 2, FALSE) -> MESA | E218: AZ | F218: 85202 | G218: Central | H218: Phoenix
A219: A-011731 | B219: Langham, David | C219: 2330 W Calle Iglesia Ave | D219: =VLOOKUP(F219, ZipTable!A:B, 2, FALSE) -> MESA | E219: AZ | F219: 85202 | G219: Central | H219: Phoenix
A220: A-034415 | B220: Perez, Kaitlin | C220: 3028 South Santa Barbara Circle | D220: =VLOOKUP(F220, ZipTable!A:B, 2, FALSE) -> MESA | E220: AZ | F220: 85202 | G220: Central | H220: Phoenix
A221: A-009027 | B221: Pruitt, Donald | C221: 2919 S Cottonwood Ln | D221: =VLOOKUP(F221, ZipTable!A:B, 2, FALSE) -> MESA | E221: AZ | F221: 85202 | G221: Central | H221: Phoenix
A222: A-002492 | B222: Thomas, Chelsea and Scott | C222: 2566 W Monte Ave | D222: =VLOOKUP(F222, ZipTable!A:B, 2, FALSE) -> MESA | E222: AZ | F222: 85202 | G222: Central | H222: Phoenix
A223: A-006607 | B223: Tran, Bac | C223: 2365 S. Paseo Loma Circle | D223: =VLOOKUP(F223, ZipTable!A:B, 2, FALSE) -> MESA | E223: AZ | F223: 85202 | G223: Central | H223: Phoenix
A224: A-066276 | B224: Azab, Bilal | C224: 1236 East Granada Street | D224: =VLOOKUP(F224, ZipTable!A:B, 2, FALSE) -> MESA | E224: AZ | F224: 85203 | G224: Central | H224: Phoenix
A225: A-008651 | B225: Breinholt, Clareen | C225: 845 N. Kachina Cir | D225: =VLOOKUP(F225, ZipTable!A:B, 2, FALSE) -> MESA | E225: AZ | F225: 85203 | G225: Central | H225: Phoenix
... A528: A-004602 | B528: Woodring, Sharro | C528: 534 W La Jolla Dr | D528: =VLOOKUP(F528, ZipTable!A:B, 2, FALSE) -> TEMPE | E528: AZ | F528: 85282 | G528: Central | H528: Phoenix

Sheet East Accounts
A1: SF Customer Number | B1: Name | C1: ShippingStreet | D1: ShippingCity | E1: ShippingStateCode | F1: ZipCode | G1: Area | H1: Source
A2: A-023883 | B2: Ahumada, Bill | C2: 4202 E Silverwood Dr | D2: =VLOOKUP(F2, ZipTable!A:B, 2, FALSE) -> PHOENIX | E2: AZ | F2: 85048 | G2: East | H2: Phoenix
A3: A-007624 | B3: Appel, Jan | C3: 1422 E Desert Trumpet Rd | D3: =VLOOKUP(F3, ZipTable!A:B, 2, FALSE) -> PHOENIX | E3: AZ | F3: 85048 | G3: East | H3: Phoenix
A4: A-007694 | B4: Becvar, Steven | C4: 205 E Mountain Sky Ave | D4: =VLOOKUP(F4, ZipTable!A:B, 2, FALSE) -> PHOENIX | E4: AZ | F4: 85048 | G4: East | H4: Phoenix
A5: A-004264 | B5: Blumenfeld, Dan & Lauren | C5: 4426 E Cottonwood Lane | D5: =VLOOKUP(F5, ZipTable!A:B, 2, FALSE) -> PHOENIX | E5: AZ | F5: 85048 | G5: East | H5: Phoenix
A6: A-001296 | B6: Cronin, Daniel | C6: 15811 S 25th Way | D6: =VLOOKUP(F6, ZipTable!A:B, 2, FALSE) -> PHOENIX | E6: AZ | F6: 85048 | G6: East | H6: Phoenix
A7: A-035246 | B7: Davis, Charles | C7: 2130 East Briarwood Terrace | D7: =VLOOKUP(F7, ZipTable!A:B, 2, FALSE) -> PHOENIX | E7: AZ | F7: 85048 | G7: East | H7: Phoenix
A8: A-068388 | B8: Davis, Helen | C8: 16834 South 20th Place | D8: =VLOOKUP(F8, ZipTable!A:B, 2, FALSE) -> PHOENIX | E8: AZ | F8: 85048 | G8: East | H8: Phoenix
A9: A-022432 | B9: Elliot, Patricia | C9: 810 E Goldenrod St | D9: =VLOOKUP(F9, ZipTable!A:B, 2, FALSE) -> PHOENIX | E9: AZ | F9: 85048 | G9: East | H9: Phoenix
A10: A-022273 | B10: Erickson, Ron & Jennifer | C10: 2524 E Desert Willow Drive | D10: =VLOOKUP(F10, ZipTable!A:B, 2, FALSE) -> PHOENIX | E10: AZ | F10: 85048 | G10: East | H10: Phoenix
A11: A-022507 | B11: Garcia, Dana | C11: 2136 E Mountain Sky Ave | D11: =VLOOKUP(F11, ZipTable!A:B, 2, FALSE) -> PHOENIX | E11: AZ | F11: 85048 | G11: East | H11: Phoenix
A12: A-023881 | B12: Gratton, Taylor | C12: 1417 E Glenhaven Dr | D12: =VLOOKUP(F12, ZipTable!A:B, 2, FALSE) -> PHOENIX | E12: AZ | F12: 85048 | G12: East | H12: Phoenix
A13: A-023885 | B13: Keene, Thomas | C13: 3620 E Saltsage Dr | D13: =VLOOKUP(F13, ZipTable!A:B, 2, FALSE) -> PHOENIX | E13: AZ | F13: 85048 | G13: East | H13: Phoenix
... A227: A-024114 | B227: Hamilton, Sandra | C227: 9011 E Hobart Street | D227: =VLOOKUP(F227, ZipTable!A:B, 2, FALSE) -> MESA | E227: AZ | F227: 85207 | G227: East | H227: Phoenix
A228: A-055262 | B228: Harris Residence | C228: 7642 East Hermosa Vista Drive | D228: =VLOOKUP(F228, ZipTable!A:B, 2, FALSE) -> MESA | F228: 85207 | G228: East | H228: Phoenix
A229: A-005547 | B229: Jacobs, Pat | C229: 8024 E. Fountain St. | D229: =VLOOKUP(F229, ZipTable!A:B, 2, FALSE) -> MESA | E229: AZ | F229: 85207 | G229: East | H229: Phoenix
A230: A-066496 | B230: James, Frank | C230: 2241 North Hillridge | D230: =VLOOKUP(F230, ZipTable!A:B, 2, FALSE) -> MESA | E230: AZ | F230: 85207 | G230: East | H230: Phoenix
A231: A-050523 | B231: Koufidakis, Angela | C231: 7544 East Laurel Street | D231: =VLOOKUP(F231, ZipTable!A:B, 2, FALSE) -> MESA | E231: AZ | F231: 85207 | G231: East | H231: Phoenix
A232: A-068557 | B232: Lanciloti, Tamara | C232: 3060 North Ridgecrest unit 172 | D232: =VLOOKUP(F232, ZipTable!A:B, 2, FALSE) -> MESA | E232: AZ | F232: 85207 | G232: East | H232: Phoenix
A233: A-056454 | B233: Looff, Kevin | C233: 9018 East Range Rider Trail | D233: =VLOOKUP(F233, ZipTable!A:B, 2, FALSE) -> MESA | E233: AZ | F233: 85207 | G233: East | H233: Phoenix
A234: A-007701 | B234: Mason, Kris | C234: 7343 E. Sierra Morena Cir. | D234: =VLOOKUP(F234, ZipTable!A:B, 2, FALSE) -> MESA | E234: AZ | F234: 85207 | G234: East | H234: Phoenix
A235: A-006597 | B235: Miroballi, Barbara | C235: 1253 N 86th Pl | D235: =VLOOKUP(F235, ZipTable!A:B, 2, FALSE) -> MESA | E235: AZ | F235: 85207 | G235: East | H235: Phoenix
A236: A-005654 | B236: Mohr, Donna | C236: 7130 E. Saddleback St. #21 | D236: =VLOOKUP(F236, ZipTable!A:B, 2, FALSE) -> MESA | E236: AZ | F236: 85207 | G236: East | H236: Phoenix
A237: A-001971 | B237: Mordhorst, Becky | C237: 9655 E Glencove Circle | D237: =VLOOKUP(F237, ZipTable!A:B, 2, FALSE) -> MESA | E237: AZ | F237: 85207 | G237: East | H237: Phoenix
A238: A-024115 | B238: Neumeyer, David & Pamela | C238: 2227 N Hillridge | D238: =VLOOKUP(F238, ZipTable!A:B, 2, FALSE) -> MESA | E238: AZ | F238: 85207 | G238: East | H238: Phoenix
A239: A-024116 | B239: Openshaw, Shane and Suzanne | C239: 7654 E Summit Trail St | D239: =VLOOKUP(F239, ZipTable!A:B, 2, FALSE) -> MESA | E239: AZ | F239: 85207 | G239: East | H239: Phoenix
A240: A-024124 | B240: Ortiz, Danielle | C240: 10326 E Cicero Cir | D240: =VLOOKUP(F240, ZipTable!A:B, 2, FALSE) -> MESA | E240: AZ | F240: 85207 | G240: East | H240: Phoenix
... A571: A-005938 | B571: Stegner, Mimi | C571: 4711 E Sourwood Dr | D571: =VLOOKUP(F571, ZipTable!A:B, 2, FALSE) -> GILBERT | E571: AZ | F571: 85298 | G571: East | H571: Phoenix

Sheet Tucson Accounts
A1: Customer_Number__c | B1: Name | C1: ShippingStreet | D1: ShippingStateCode | E1: ShippingPostalCode | F1: ZipCode | G1: Area | H1: Source | I1: ShippingCity
A2: A-023308 | B2: American Homes 4 Rent AZ12353 - Maintenance - 10/ 27/2022 | C2: 10864 E Scenic Veranda Drive | D2: AZ | E2: 85641 | F2: 85641 | G2: Tucson | H2: Tucson | I2: Vail
A3: A-064405 | B3: Lamie Residence - Maintenance - 07/ 29/2024 | C3: 13785 E Silver Pine Trail | D3: AZ | E3: 85641 | F3: 85641 | G3: Tucson | H3: Tucson | I3: Vail
A4: A-050513 | B4: Hege Residence - Maintenance - 07/ 14/2022 | C4: 11550 West Kalamansi Drive | D4: AZ | E4: 85653 | F4: 85653 | G4: Tucson | H4: Tucson | I4: Marana
A5: A-013331 | B5: Brooks Residence - Maintenance - 07/ 16/2024 | C5: 5350 W. Twin Peaks Rd. | D5: AZ | E5: 85658 | F5: 85658 | G5: Tucson | H5: Tucson | I5: Marana
A6: A-028431 | B6: Cutlip Residence - Maintenance - Ongoing (Winter and Summer) - 2019-04-18 | C6: 4619 W Horizon Ridge Drive | D6: AZ | E6: 85658 | F6: 85658 | G6: Tucson | H6: Tucson | I6: Marana
A7: A-031163 | B7: Masterson Residence - Maintenance - 01/ 28/2021 | C7: 4082 West Adobe Ranch Place | D7: AZ | E7: 85658 | F7: 85658 | G7: Tucson | H7: Tucson | I7: Marana
A8: A-068714 | B8: Sloan, Connie - Maintenance - 07/ 02/2025 | C8: 6611 West Antler Bend Place | D8: AZ | E8: 85658 | F8: 85658 | G8: Tucson | H8: Tucson | I8: Marana
A9: A-032918 | B9: Torgerson Residence - Maintenance - 05/ 06/2021 | C9: 6977 W River Trail | D9: AZ | E9: 85658 | F9: 85658 | G9: Tucson | H9: Tucson | I9: Marana
A10: A-068211 | B10: Burchette, Robert - Maintenance - 05/ 23/2025 | C10: 6562 North Pomona Road | D10: AZ | E10: 85704 | F10: 85704 | G10: Tucson | H10: Tucson | I10: Tucson
A11: A-067375 | B11: Pobrislo, Jim - Maintenance - 02/ 25/2025 | C11: 5535 North Grande Avenue | D11: AZ | E11: 85704 | F11: 85704 | G11: Tucson | H11: Tucson | I11: Tucson
A12: A-050106 | B12: Thomas Residence - Maintenance - 06/ 21/2022 | C12: 5520 North Northern Hills Drive | D12: AZ | E12: 85704 | F12: 85704 | G12: Tucson | H12: Tucson | I12: Tucson
A13: A-068550 | B13: Olivarez, Fernando - Maintenance - 06/ 23/2025 | C13: 818 West Kelso Street | D13: AZ | E13: 85705 | F13: 85705 | G13: Tucson | H13: Tucson | I13: Tucson
... A74: A-067899 | B74: Hurtado, Araceli - Maintenance - 04/ 28/2025 | C74: 6681 West Brightwater Way | D74: AZ | E74: 85757 | F74: 85757 | G74: Tucson | H74: Tucson | I74: Tucson

Sheet ZipTable
A1: zip | B1: City | C1: County Name
A2: 85320 | B2: AGUILA | C2: MARICOPA
A3: 85321 | B3: AJO | C3: PIMA
A4: 85920 | B4: ALPINE | C4: APACHE
A5: 85645 | B5: AMADO | C5: PIMA
A6: 85117 | B6: APACHE JUNCTION | C6: PINAL
A7: 85119 | B7: APACHE JUNCTION | C7: PINAL
A8: 85120 | B8: APACHE JUNCTION | C8: PINAL
A9: 85178 | B9: APACHE JUNCTION | C9: PINAL
A10: 85601 | B10: ARIVACA | C10: PIMA
A11: 85123 | B11: ARIZONA CITY | C11: PINAL
A12: 85322 | B12: ARLINGTON | C12: MARICOPA
A13: 86320 | B13: ASH FORK | C13: YAVAPAI
... A517: 85369 | B517: YUMA | C517: YUMA
A520: For more information, kindly visit: www.downloadexcelfiles.com
